Workbook

Sheet Data
A2: Year | B2: JUL | C2: PO No. | D2: Supplier Name. | E2: Description of Goods/Service | F2: Qty | G2: Unit | H2: ราคาต่ำสุดต่อหน่วย | I2: ราคารวม | J2: ราคาที่ต่อรองได้ | K2: ผลต่าง | L2: รวมที่ต่อรองได้ | M2: % discount | N2: Method for discounts | O2: Person in charge
A3: 2023 | B3: JAN | C3: PO-23000001 | D3: บริษัท เอทีซี อินดัสตรี (ประเทศไทย)จำกัด | E3: ทินเนอร์ THINNER AAA | F3: 36 | G3: EA | H3: 460 | I3: =H3*F3 -> 16560 | J3: 420 | K3: =H3-J3 -> 40 | L3: =K3*F3 -> 1440 | M3: =K3/H3 -> 0.086956522 | N3: Avoidance | O3: Saniya | P3: Compare + Negotiate
A4: 2023 | B4: JAN | C4: PO-23000002 | D4: บริษัท เอ็นทีดับเบิ้ลยู เอ็นจิเนียริ่ง ซัพพลาย จำกัด | E4: สีสเปรย์ KOBE สีดำด้าน เบอร์ 912 | F4: 36 | G4: EA | H4: 44.5 | I4: =H4*F4 -> 1602 | J4: 39 | K4: =H4-J4 -> 5.5 | L4: =K4*F4 -> 198 | M4: =K4/H4 -> 0.12359551 | N4: Compare + Negotiate | O4: Saniya | P4: Avoidance
A5: 2023 | B5: JAN | C5: PO-23000016 | D5: บริษัท บ้านไฟฟ้า จำกัด | E5: สายไฟ H07V-K 1*1.5 SQ.MM. GNYE (สีเขียวแถบเหลือง) | F5: 2 | G5: Roll | H5: 1200 | I5: =H5*F5 -> 2400 | J5: 990 | K5: =H5-J5 -> 210 | L5: =K5*F5 -> 420 | M5: =K5/H5 -> 0.175 | N5: Compare + Negotiate | O5: Saniya | P5: เพิ่มเครดิต
A6: 2023 | B6: JAN | C6: PO-23000077 | D6: บริษัท เอทีซี อินดัสตรี (ประเทศไทย)จำกัด | E6: สก๊อตเทปใส Unitape size 1/2" IN x 72 YDS | F6: 576 | G6: Roll | H6: 28 | I6: =H6*F6 -> 16128 | J6: 25 | K6: =H6-J6 -> 3 | L6: =K6*F6 -> 1728 | M6: =K6/H6 -> 0.10714286 | N6: Avoidance | O6: Saniya | P6: Rebate
A7: 2023 | B7: JAN | C7: PO-23000087 | D7: ห้างหุ้นส่วนจำกัด บางกอกคอปเปอร์ | E7: ลวดแบนหุ้มกระดาษหนา 0.5 มม. ขนาด 3.0*13 มม. | F7: 1893 | G7: KG | H7: 360 | I7: =H7*F7 -> 681480 | J7: 359.5 | K7: =H7-J7 -> 0.5 | L7: =K7*F7 -> 946.5 | M7: =K7/H7 -> 0.0013888889 | N7: Negotiate | O7: Pawina | P7: Negotiate
A8: 2023 | B8: JAN | C8: PO-23000087 | D8: ห้างหุ้นส่วนจำกัด บางกอกคอปเปอร์ | E8: ลวดแบนหุ้มกระดาษหนา 0.5 มม. ขนาด 3.0*13 มม. | F8: 1893 | G8: KG | H8: 360 | I8: =H8*F8 -> 681480 | J8: 359.5 | K8: =H8-J8 -> 0.5 | L8: =K8*F8 -> 946.5 | M8: =K8/H8 -> 0.0013888889 | N8: Negotiate | O8: Pawina
A9: 2023 | B9: JAN | C9: PO-23000087 | D9: ห้างหุ้นส่วนจำกัด บางกอกคอปเปอร์ | E9: ลวดแบนหุ้มกระดาษหนา 0.5 มม. ขนาด 2.8*11 มม. | F9: 110 | G9: KG | H9: 360 | I9: =H9*F9 -> 39600 | J9: 359.5 | K9: =H9-J9 -> 0.5 | L9: =K9*F9 -> 55 | M9: =K9/H9 -> 0.0013888889 | N9: Negotiate | O9: Pawina
A10: 2023 | B10: JAN | C10: PO-23000087 | D10: ห้างหุ้นส่วนจำกัด บางกอกคอปเปอร์ | E10: ลวดแบนหุ้มกระดาษหนา 0.5 มม. ขนาด 1.8 *4.0 มม. | F10: 321 | G10: KG | H10: 360 | I10: =H10*F10 -> 115560 | J10: 359.5 | K10: =H10-J10 -> 0.5 | L10: =K10*F10 -> 160.5 | M10: =K10/H10 -> 0.0013888889 | N10: Negotiate | O10: Pawina
A11: 2023 | B11: JAN | C11: PO-23000014 | D11: บริษัท ตงเฉินอีเล็คทริคเคเบิ้ลแอนด์ ไวร์ จำกัด | E11: ลวดกลมอาบน้ำยา ขนาด 1.50 มม. | F11: 593.27 | G11: KG | H11: 346 | I11: =H11*F11 -> 205271.42 | J11: 334 | K11: =H11-J11 -> 12 | L11: =K11*F11 -> 7119.24 | M11: =K11/H11 -> 0.034682081 | N11: Negotiate | O11: Pawina
A12: 2023 | B12: JAN | C12: PO-23000014 | D12: บริษัท ตงเฉินอีเล็คทริคเคเบิ้ลแอนด์ ไวร์ จำกัด | E12: ลวดกลมอาบน้ำยา ขนาด 1.40 มม. | F12: 295.02 | G12: KG | H12: 346 | I12: =H12*F12 -> 102076.92 | J12: 334.5 | K12: =H12-J12 -> 11.5 | L12: =K12*F12 -> 3392.73 | M12: =K12/H12 -> 0.033236994 | N12: Negotiate | O12: Pawina
A13: 2023 | B13: JAN | C13: PO-23000014 | D13: บริษัท ตงเฉินอีเล็คทริคเคเบิ้ลแอนด์ ไวร์ จำกัด | E13: ลวดกลมอาบน้ำยา ขนาด 1.50 มม. | F13: 688.13 | G13: KG | H13: 346 | I13: =H13*F13 -> 238092.98 | J13: 334 | K13: =H13-J13 -> 12 | L13: =K13*F13 -> 8257.56 | M13: =K13/H13 -> 0.034682081 | N13: Negotiate | O13: Pawina
A14: 2023 | B14: JAN | C14: PO-23000014 | D14: บริษัท ตงเฉินอีเล็คทริคเคเบิ้ลแอนด์ ไวร์ จำกัด | E14: ลวดกลมอาบน้ำยา ขนาด 0.95 มม. | F14: 607.18 | G14: KG | H14: 349 | I14: =H14*F14 -> 211905.82 | J14: 338.5 | K14: =H14-J14 -> 10.5 | L14: =K14*F14 -> 6375.39 | M14: =K14/H14 -> 0.03008596 | N14: Negotiate | O14: Pawina
A15: 2023 | B15: JAN | C15: PO-23000014 | D15: บริษัท ตงเฉินอีเล็คทริคเคเบิ้ลแอนด์ ไวร์ จำกัด | E15: ลวดกลมอาบน้ำยา ขนาด 0.75 มม. | F15: 101.67 | G15: KG | H15: 350 | I15: =H15*F15 -> 35584.5 | J15: 340 | K15: =H15-J15 -> 10 | L15: =K15*F15 -> 1016.7 | M15: =K15/H15 -> 0.028571429 | N15: Negotiate | O15: Pawina
A16: 2023 | B16: JAN | C16: PO-23000014 | D16: บริษัท ตงเฉินอีเล็คทริคเคเบิ้ลแอนด์ ไวร์ จำกัด | E16: ลวดกลมอาบน้ำยา ขนาด 1.20 มม. | F16: 700.27 | G16: KG | H16: 348 | I16: =H16*F16 -> 243693.96 | J16: 334 | K16: =H16-J16 -> 14 | L16: =K16*F16 -> 9803.78 | M16: =K16/H16 -> 0.040229885 | N16: Negotiate | O16: Pawina
A17: 2023 | B17: JAN | C17: PO-23000014 | D17: บริษัท ตงเฉินอีเล็คทริคเคเบิ้ลแอนด์ ไวร์ จำกัด | E17: ลวดกลมอาบน้ำยา ขนาด 0.90 มม. | F17: 256.35 | G17: KG | H17: 349 | I17: =H17*F17 -> 89466.15 | J17: 338.5 | K17: =H17-J17 -> 10.5 | L17: =K17*F17 -> 2691.675 | M17: =K17/H17 -> 0.03008596 | N17: Negotiate | O17: Pawina
A18: 2023 | B18: JAN | C18: PO-23000014 | D18: บริษัท ตงเฉินอีเล็คทริคเคเบิ้ลแอนด์ ไวร์ จำกัด | E18: ลวดกลมอาบน้ำยา ขนาด 1.10 มม. | F18: 101.18 | G18: KG | H18: 348 | I18: =H18*F18 -> 35210.64 | J18: 337 | K18: =H18-J18 -> 11 | L18: =K18*F18 -> 1112.98 | M18: =K18/H18 -> 0.031609195 | N18: Negotiate | O18: Pawina
A19: 2023 | B19: JAN | C19: PO-23000014 | D19: บริษัท ตงเฉินอีเล็คทริคเคเบิ้ลแอนด์ ไวร์ จำกัด | E19: ลวดกลมอาบน้ำยา ขนาด 1.10 มม. | F19: 370.41 | G19: KG | H19: 348 | I19: =H19*F19 -> 128902.68 | J19: 337 | K19: =H19-J19 -> 11 | L19: =K19*F19 -> 4074.51 | M19: =K19/H19 -> 0.031609195 | N19: Negotiate | O19: Pawina
... A62: 2023 | B62: JAN | C62: PO-23000265 | D62: บริษัท ไทยพัฒนสิน (จิ้นเส็ง 2000) จำกัด | E62: ปืนเป่าลมUnior#1508Aขนาด4นิ้วยาว260มิล (เทสรั่ว ของคมกริช) | F62: 6 | G62: EA | H62: 250 | I62: =H62*F62 -> 1500 | J62: 185 | K62: =H62-J62 -> 65 | L62: =K62*F62 -> 390 | M62: =K62/H62 -> 0.26 | N62: Compare + Negotiate | O62: Saniya
A63: 2023 | B63: JAN | C63: PO-23000266 | D63: บริษัท เอทีซี อินดัสตรี (ประเทศไทย)จำกัด | E63: ฝาครอบป้องกันเลื่อยวงเดือน 10-12 นิ้ว พร้อมขายึด | F63: 1 | H63: 3500 | I63: =H63*F63 -> 3500 | J63: 750 | K63: =H63-J63 -> 2750 | L63: =K63*F63 -> 2750 | M63: =K63/H63 -> 0.78571429 | N63: Compare + Negotiate | O63: Saniya
A64: 2023 | B64: JAN | C64: PO-23000282 | D64: ห้างหุ้นส่วนจำกัด บางกอกคอปเปอร์ | E64: ลวดแบนหุ้มกระดาษหนา 0.5 มม. ขนาด 1.4*8.5 มม. | F64: 1053 | G64: KG | H64: 360 | I64: =H64*F64 -> 379080 | J64: 359.5 | K64: =H64-J64 -> 0.5 | L64: =K64*F64 -> 526.5 | M64: =K64/H64 -> 0.0013888889 | N64: Negotiate | O64: Tanida
A65: 2023 | B65: JAN | C65: PO-23000282 | D65: ห้างหุ้นส่วนจำกัด บางกอกคอปเปอร์ | E65: ลวดแบนหุ้มกระดาษหนา 0.5 มม. ขนาด 1.4*8.5 มม. | F65: 1053 | G65: KG | H65: 360 | I65: =H65*F65 -> 379080 | J65: 359.5 | K65: =H65-J65 -> 0.5 | L65: =K65*F65 -> 526.5 | M65: =K65/H65 -> 0.0013888889 | N65: Negotiate | O65: Tanida
A66: 2023 | B66: JAN | C66: PO-23000333 | D66: บริษัท สกิลทูลแอนด์เซอร์วิส จำกัด | E66: เหล็กดูดแรงสูง นีโอไดเมียม D2503 : 25mm. x 3mm. | F66: 20 | G66: EA | H66: 48 | I66: =H66*F66 -> 960 | J66: 45 | K66: =H66-J66 -> 3 | L66: =K66*F66 -> 60 | M66: =K66/H66 -> 0.0625 | N66: Compare + Negotiate | O66: Tanida
A67: 2023 | B67: JAN | C67: PO-23000298 | D67: บริษัท สกิลทูลแอนด์เซอร์วิส จำกัด | E67: เครื่องเจียร์ BOSCH รุ่น GWS900-100S | F67: 1 | G67: EA | H67: 2800 | I67: =H67*F67 -> 2800 | J67: 2500 | K67: =H67-J67 -> 300 | L67: =K67*F67 -> 300 | M67: =K67/H67 -> 0.10714286 | N67: Compare + Negotiate | O67: Saniya
A68: 2023 | B68: JAN | C68: PO-23000298 | D68: บริษัท สกิลทูลแอนด์เซอร์วิส จำกัด | E68: สว่านโรตารี่ 3 ระบบ GBH 2-26 DFR BOSCH | F68: 1 | G68: EA | H68: 7000 | I68: =H68*F68 -> 7000 | J68: 6500 | K68: =H68-J68 -> 500 | L68: =K68*F68 -> 500 | M68: =K68/H68 -> 0.071428571 | N68: Compare + Negotiate | O68: Saniya
A69: 2023 | B69: JAN | C69: PO-23000298 | D69: บริษัท สกิลทูลแอนด์เซอร์วิส จำกัด | E69: เครื่องแว็คคั่ม ยี่ห้อ VALUE รุ่น VE225N | F69: 1 | G69: EA | H69: 4990 | I69: =H69*F69 -> 4990 | J69: 4500 | K69: =H69-J69 -> 490 | L69: =K69*F69 -> 490 | M69: =K69/H69 -> 0.098196393 | N69: Compare + Negotiate | O69: Saniya
A70: 2023 | B70: JAN | C70: PO-23000298 | D70: บริษัท สกิลทูลแอนด์เซอร์วิส จำกัด | E70: สว่านโรตารี่ไร้สายระบบ SDS plus GBH 180-LI | F70: 1 | G70: EA | H70: 10900 | I70: =H70*F70 -> 10900 | J70: 9600 | K70: =H70-J70 -> 1300 | L70: =K70*F70 -> 1300 | M70: =K70/H70 -> 0.11926606 | N70: Compare + Negotiate | O70: Saniya
A71: 2023 | B71: JAN | C71: PO-23000299 | D71: บริษัท แสงชัยมิเตอร์ จำกัด | E71: เครื่องทดสอบความต้านทานดิน KYORITSU 4105A-H | F71: 1 | G71: EA | H71: 13000 | I71: =H71*F71 -> 13000 | J71: 10240 | K71: =H71-J71 -> 2760 | L71: =K71*F71 -> 2760 | M71: =K71/H71 -> 0.21230769 | N71: Compare + Negotiate | O71: Saniya
A72: 2023 | B72: JAN | C72: PO-23000334 | D72: บริษัท แคเรีย เทคโนโลยี (ประเทศไทย) จำกัด | E72: Transfomer Oil Gas Analyzer " Agilent " Model: 8890 | F72: 1 | G72: set | H72: 4076000 | I72: =H72*F72 -> 4076000 | J72: 4000000 | K72: =H72-J72 -> 76000 | L72: =K72*F72 -> 76000 | M72: =K72/H72 -> 0.018645731 | N72: Negotiate | O72: Saniya
A73: 2023 | B73: JAN | C73: PO-23000335 | D73: บริษัท เอทีซี อินดัสตรี (ประเทศไทย)จำกัด | E73: ปืนเป่าลมร้อน HEATGUN BOSCH รุ่นGHG 20-63 2000W. | F73: 1 | G73: EA | H73: 4029 | I73: =H73*F73 -> 4029 | J73: 3850 | K73: =H73-J73 -> 179 | L73: =K73*F73 -> 179 | M73: =K73/H73 -> 0.044427898 | N73: Compare + Negotiate | O73: Saniya
A74: 2023 | B74: JAN | C74: PO-23000336 | D74: บริษัท เอ็นทีดับเบิ้ลยู เอ็นจิเนียริ่ง ซัพพลาย จำกัด | E74: สีสเปรย์ KOBE สีดำด้าน เบอร์ 912 | F74: 36 | G74: EA | H74: 44.5 | I74: =H74*F74 -> 1602 | J74: 39 | K74: =H74-J74 -> 5.5 | L74: =K74*F74 -> 198 | M74: =K74/H74 -> 0.12359551 | N74: Compare + Negotiate | O74: Saniya
A75: 2023 | B75: JAN | C75: PO-23000285 | D75: Wuhu Zhongyuan Import and Export Co.,Ltd | E75: Copper Foil ขนาด 0.40*340 มม. | F75: 1460 | G75: KG | H75: 33.165 | I75: =H75*F75 -> 48420.9 | J75: 32.505 | K75: =H75-J75 -> 0.66 | L75: =K75*F75 -> 963.6 | M75: =K75/H75 -> 0.019900498 | N75: Negotiate | O75: Tanida
... A112: 2023 | B112: FEB | C112: PO-23000401 | D112: บริษัท สกิลทูลแอนด์เซอร์วิส จำกัด | E112: ไม้บรรทัด 2 เมตร 78นิ้ว ฟุตเหล็กสแตนเลส ENDO KEIKI | F112: 1 | G112: EA | H112: 3300 | I112: =H112*F112 -> 3300 | J112: 3000 | K112: =H112-J112 -> 300 | L112: =K112*F112 -> 300 | M112: =K112/H112 -> 0.090909091 | N112: Negotiate | O112: Tanida
A113: 2023 | B113: FEB | C113: PO-23000381,PO-23000453 | D113: บริษัท เอคเม อินซูเลชั่น จำกัด | E113: Wheel Dia.200 mm. thick type/2holes | F113: 124 | G113: EA | H113: 3545 | I113: =H113*F113 -> 439580 | J113: 3365 | K113: =H113-J113 -> 180 | L113: =K113*F113 -> 22320 | M113: =K113/H113 -> 0.05077574 | N113: Negotiate
A114: 2023 | B114: FEB | C114: PO-23000485 | D114: บริษัท ศูนย์บริการเหล็กสยาม จำกัด (มหาชน) | E114: Cold Rolled Steel Sheet (SPCC-SD) ขนาด 1.5*900 มม. | F114: 3000 | G114: kg. | H114: 35 | I114: =H114*F114 -> 105000 | J114: 34.7 | K114: =H114-J114 -> 0.3 | L114: =K114*F114 -> 900 | M114: =K114/H114 -> 0.0085714286 | N114: Compare + Negotiate | O114: Pawina
A115: 2023 | B115: FEB | C115: PO-23000455 | D115: บริษัท ศูนย์บริการเหล็กสยาม จำกัด (มหาชน) | E115: Cold Rolled Steel Sheet (SPCC-SD) ขนาด 1.5*1200 มม. | F115: 6000 | G115: kg. | H115: 35 | I115: =H115*F115 -> 210000 | J115: 34.5 | K115: =H115-J115 -> 0.5 | L115: =K115*F115 -> 3000 | M115: =K115/H115 -> 0.014285714 | N115: Compare + Negotiate | O115: Pawina
A116: 2023 | B116: FEB | C116: PO-23000519 | D116: บริษัท ศูนย์บริการเหล็กสยาม จำกัด (มหาชน) | E116: Cold Rolled Steel Sheet (SPCC-SD) ขนาด 1.5*1200 มม. | F116: 6000 | G116: kg. | H116: 35 | I116: =H116*F116 -> 210000 | J116: 34.5 | K116: =H116-J116 -> 0.5 | L116: =K116*F116 -> 3000 | M116: =K116/H116 -> 0.014285714 | N116: Compare + Negotiate | O116: Pawina
A117: 2023 | B117: FEB | C117: PO-23000431 | D117: บริษัท ไทย ซูปาโก้ เอ็นจิเนียริ่ง แอนด์ ซัพพลาย จำกัด | E117: HARRIS ชุด ตัด Model : 625F LPG | F117: 1 | G117: Set | H117: 5990 | I117: =H117*F117 -> 5990 | J117: 5172.75 | K117: =H117-J117 -> 817.25 | L117: =K117*F117 -> 817.25 | M117: =K117/H117 -> 0.13643573 | N117: Compare + Negotiate | O117: Saniya
A118: 2023 | B118: FEB | C118: PO-23000431 | D118: บริษัท ไทย ซูปาโก้ เอ็นจิเนียริ่ง แอนด์ ซัพพลาย จำกัด | E118: HARRIS เกร์ลม Model : 801DB-10-Oxygen | F118: 1 | G118: set | H118: 2725 | I118: =H118*F118 -> 2725 | J118: 2523.66 | K118: =H118-J118 -> 201.34 | L118: =K118*F118 -> 201.34 | M118: =K118/H118 -> 0.073886239 | N118: Compare + Negotiate | O118: Saniya
A119: 2023 | B119: FEB | C119: PO-23000431 | D119: บริษัท ไทย ซูปาโก้ เอ็นจิเนียริ่ง แอนด์ ซัพพลาย จำกัด | E119: LONGWELL เกย์ CO2 พร้อมฮีตเตอร์ CR-220V | F119: 1 | G119: Set | H119: 2800 | I119: =H119*F119 -> 2800 | J119: 1567.5 | K119: =H119-J119 -> 1232.5 | L119: =K119*F119 -> 1232.5 | M119: =K119/H119 -> 0.44017857 | N119: Compare + Negotiate | O119: Saniya
...

Sheet สรุป-รายเดือน
A1: เดือน | B1: 2021 | E1: สรุปผล | F1: COST REDUCTION | J1: สรุปผล | L1: Year | M1: 2026
B2: มูลค่าซื้อ | C2: มูลค่าที่ลดลง | D2: คิดเป็น % | F2: มูลค่าซื้อ | G2: มูลค่าต่อรองได้ | H2: มูลค่าเป้าหมาย 3% | I2: คิดเป็น % | P2: % | Q2: เดือน | R2: เงื่อนไขเดิม | S2: เงื่อนไขใหม่ | T2: ผลต่าง | U2: มูลค่าสั่งซื้อ | V2: ลดต้นทุนทางบัญชี | X2: มูลค่าหลังหักส่วนลดเครดดิต
A3: JAN | B3: 35429481 | C3: 2064228.4 | D3: =IF(B3="","",(C3/B3)*100) -> 5.8263014 | E3: =IF(D3="","",IF(D3>=3,$A$47,$A$48)) -> ได้ตามเป้าหมาย | F3: =มูลค่าซื้อ!D3 -> 1.215226e+08 | G3: =SUMIFS(Data!$L$3:$L$9021,Data!$B$3:$B$9021,'สรุป-รายเดือน'!$A3,Data!$A$3:$A$9021,'สรุป-รายเดือน'!$M$1) -> 8059232.2 | H3: =F3*0.03 -> 3645678.1 | I3: =(G3/F3)*100 -> 6.6318791 | J3: =IF(I3="","",IF(I3>=3,$A$47,$A$48)) -> ได้ตามเป้าหมาย | L3: =G3-H3 -> 4413554.1 | M3: =L3/F3 -> 0.036318791 | V3: อัตราดอกเบี้ย 4.25% ต่อปี
A4: FEB | B4: 46183144 | C4: 490222.25 | D4: =IF(B4="","",(C4/B4)*100) -> 1.0614744 | E4: =IF(D4="","",IF(D4>=3,$A$47,$A$48)) -> ไม่ได้ตามเป้าหมาย | F4: =มูลค่าซื้อ!D4 -> 69378145 | G4: =SUMIFS(Data!$L$3:$L$9021,Data!$B$3:$B$9021,'สรุป-รายเดือน'!$A4,Data!$A$3:$A$9021,'สรุป-รายเดือน'!$M$1) -> 1780587.7 | H4: =F4*0.03 -> 2081344.4 | I4: =(G4/F4)*100 -> 2.5664966 | J4: =IF(I4="","",IF(I4>=3,$A$47,$A$48)) -> ไม่ได้ตามเป้าหมาย | L4: =G4-H4 -> -300756.65 | M4: =L4/H4 -> -0.14450115 | R4: 0 | S4: 15 | T4: =S4-R4 -> 15 | U4: 515000 | V4: =(U4*4.25%)*30/360 -> 1823.9583 | W4: =V4/U4 -> 0.0035416667 | X4: =U4-V4 -> 513176.04
A5: MAR | B5: 54764339 | C5: 1120405.4 | D5: =IF(B5="","",(C5/B5)*100) -> 2.0458667 | E5: =IF(D5="","",IF(D5>=3,$A$47,$A$48)) -> ไม่ได้ตามเป้าหมาย | F5: 1.2676433e+08 | G5: =SUMIFS(Data!$L$3:$L$9021,Data!$B$3:$B$9021,'สรุป-รายเดือน'!$A5,Data!$A$3:$A$9021,'สรุป-รายเดือน'!$M$1) -> 3857396.5 | H5: =F5*0.03 -> 3802930 | I5: =(G5/F5)*100 -> 3.0429668 | J5: =IF(I5="","",IF(I5>=3,$A$47,$A$48)) -> ได้ตามเป้าหมาย | L5: =G5-H5 -> 54466.529 | M5: =L5/H5 -> 0.014322254 | R5: 0 | S5: 30 | T5: =S5-R5 -> 30 | U5: 2595435.5 | V5: =(U5*4.25%)*30/360 -> 9192.1674 | W5: =V5/U5 -> 0.0035416667 | X5: =U5-V5 -> 2586243.3
A6: APR | B6: 32497324 | C6: 356214.95 | D6: =IF(B6="","",(C6/B6)*100) -> 1.0961362 | E6: =IF(D6="","",IF(D6>=3,$A$47,$A$48)) -> ไม่ได้ตามเป้าหมาย | F6: 57832810 | G6: =SUMIFS(Data!$L$3:$L$9021,Data!$B$3:$B$9021,'สรุป-รายเดือน'!$A6,Data!$A$3:$A$9021,'สรุป-รายเดือน'!$M$1) -> 739724.92 | H6: =F6*0.03 -> 1734984.3 | I6: =(G6/F6)*100 -> 1.2790748 | J6: =IF(I6="","",IF(I6>=3,$A$47,$A$48)) -> ไม่ได้ตามเป้าหมาย | L6: =G6-H6 -> -995259.38 | M6: =L6/H6 -> -0.57364172 | R6: 30 | S6: 60 | T6: =S6-R6 -> 30 | U6: 3340000 | V6: =(U6*4.25%)*30/360 -> 11829.167 | W6: =V6/U6 -> 0.0035416667 | X6: =U6-V6 -> 3328170.8
A7: MAY | B7: 43171991 | C7: 1477519.8 | D7: =IF(B7="","",(C7/B7)*100) -> 3.4224036 | E7: =IF(D7="","",IF(D7>=3,$A$47,$A$48)) -> ได้ตามเป้าหมาย | F7: 66134405 | G7: =SUMIFS(Data!$L$3:$L$9021,Data!$B$3:$B$9021,'สรุป-รายเดือน'!$A7,Data!$A$3:$A$9021,'สรุป-รายเดือน'!$M$1) -> 1641950.6 | H7: =F7*0.03 -> 1984032.1 | I7: =(G7/F7)*100 -> 2.482748 | J7: =IF(I7="","",IF(I7>=3,$A$47,$A$48)) -> ไม่ได้ตามเป้าหมาย | L7: =G7-H7 -> -342081.55 | M7: =L7/H7 -> -0.17241734
A8: JUN | B8: 58552221 | C8: 612132.27 | D8: =IF(B8="","",(C8/B8)*100) -> 1.0454467 | E8: =IF(D8="","",IF(D8>=3,$A$47,$A$48)) -> ไม่ได้ตามเป้าหมาย | F8: 92229828 | G8: =SUMIFS(Data!$L$3:$L$9021,Data!$B$3:$B$9021,'สรุป-รายเดือน'!$A8,Data!$A$3:$A$9021,'สรุป-รายเดือน'!$M$1) -> 6009822.5 | H8: =F8*0.03 -> 2766894.8 | I8: =(G8/F8)*100 -> 6.5161376 | J8: =IF(I8="","",IF(I8>=3,$A$47,$A$48)) -> ได้ตามเป้าหมาย | L8: =G8-H8 -> 3242927.6 | M8: =L8/H8 -> 1.1720459
A9: JUL | B9: 63322616 | C9: 266870.85 | D9: =IF(B9="","",(C9/B9)*100) -> 0.42144634 | E9: =IF(D9="","",IF(D9>=3,$A$47,$A$48)) -> ไม่ได้ตามเป้าหมาย | F9: 1.1134741e+08 | G9: =SUMIFS(Data!$L$3:$L$9021,Data!$B$3:$B$9021,'สรุป-รายเดือน'!$A9,Data!$A$3:$A$9021,'สรุป-รายเดือน'!$M$1) -> 4132770.9 | H9: =F9*0.03 -> 3340422.2 | I9: =(G9/F9)*100 -> 3.7116005 | J9: =IF(I9="","",IF(I9>=3,$A$47,$A$48)) -> ได้ตามเป้าหมาย | L9: =G9-H9 -> 792348.68 | M9: =L9/H9 -> 0.23720016
A10: AUG | B10: 67114435 | C10: 846288.4 | D10: =IF(B10="","",(C10/B10)*100) -> 1.2609633 | E10: =IF(D10="","",IF(D10>=3,$A$47,$A$48)) -> ไม่ได้ตามเป้าหมาย | F10: =SUMIFS(มูลค่าซื้อ!$D$15:$D$1012,มูลค่าซื้อ!$C$15:$C$1012,'สรุป-รายเดือน'!$A10,มูลค่าซื้อ!$B$15:$B$1012,'สรุป-รายเดือน'!$M$1) -> 0 | G10: =SUMIFS(Data!$L$3:$L$9021,Data!$B$3:$B$9021,'สรุป-รายเดือน'!$A10,Data!$A$3:$A$9021,'สรุป-รายเดือน'!$M$1) -> -435915.2 | H10: =F10*0.03 -> 0 | I10: =(G10/F10)*100 -> #DIV/0! | J10: =IF(I10="","",IF(I10>=3,$A$47,$A$48)) -> #DIV/0! | L10: =G10-H10 -> -435915.2 | M10: =L10/H10 -> #DIV/0!
A11: SEP | B11: 78087740 | C11: 587687.39 | D11: =IF(B11="","",(C11/B11)*100) -> 0.75259878 | E11: =IF(D11="","",IF(D11>=3,$A$47,$A$48)) -> ไม่ได้ตามเป้าหมาย | F11: =SUMIFS(มูลค่าซื้อ!$D$15:$D$1012,มูลค่าซื้อ!$C$15:$C$1012,'สรุป-รายเดือน'!$A11,มูลค่าซื้อ!$B$15:$B$1012,'สรุป-รายเดือน'!$M$1) -> 0 | G11: =SUMIFS(Data!$L$3:$L$9021,Data!$B$3:$B$9021,'สรุป-รายเดือน'!$A11,Data!$A$3:$A$9021,'สรุป-รายเดือน'!$M$1) -> 0 | H11: =F11*0.03 -> 0 | I11: =(G11/F11)*100 -> #DIV/0! | J11: =IF(I11="","",IF(I11>=3,$A$47,$A$48)) -> #DIV/0! | L11: =G11-H11 -> 0 | M11: =L11/H11 -> #DIV/0!
A12: OCT | B12: 51614276 | C12: 729979.18 | D12: =IF(B12="","",(C12/B12)*100) -> 1.414297 | E12: =IF(D12="","",IF(D12>=3,$A$47,$A$48)) -> ไม่ได้ตามเป้าหมาย | F12: =SUMIFS(มูลค่าซื้อ!$D$15:$D$1012,มูลค่าซื้อ!$C$15:$C$1012,'สรุป-รายเดือน'!$A12,มูลค่าซื้อ!$B$15:$B$1012,'สรุป-รายเดือน'!$M$1) -> 0 | G12: =SUMIFS(Data!$L$3:$L$9021,Data!$B$3:$B$9021,'สรุป-รายเดือน'!$A12,Data!$A$3:$A$9021,'สรุป-รายเดือน'!$M$1) -> 0 | H12: =F12*0.03 -> 0 | I12: =(G12/F12)*100 -> #DIV/0! | J12: =IF(I12="","",IF(I12>=3,$A$47,$A$48)) -> #DIV/0! | L12: =G12-H12 -> 0 | M12: =L12/H12 -> #DIV/0!
A13: NOV | B13: 1.5306232e+08 | C13: 976139.6 | D13: =IF(B13="","",(C13/B13)*100) -> 0.63773999 | E13: =IF(D13="","",IF(D13>=3,$A$47,$A$48)) -> ไม่ได้ตามเป้าหมาย | F13: =SUMIFS(มูลค่าซื้อ!$D$15:$D$1012,มูลค่าซื้อ!$C$15:$C$1012,'สรุป-รายเดือน'!$A13,มูลค่าซื้อ!$B$15:$B$1012,'สรุป-รายเดือน'!$M$1) -> 0 | G13: =SUMIFS(Data!$L$3:$L$9021,Data!$B$3:$B$9021,'สรุป-รายเดือน'!$A13,Data!$A$3:$A$9021,'สรุป-รายเดือน'!$M$1) -> 0 | H13: =F13*0.03 -> 0 | I13: =(G13/F13)*100 -> #DIV/0! | J13: =IF(I13="","",IF(I13>=3,$A$47,$A$48)) -> #DIV/0! | L13: =G13-H13 -> 0 | M13: =L13/H13 -> #DIV/0!
A14: DEC | B14: 19994700 | C14: 66880.267 | D14: =IF(B14="","",(C14/B14)*100) -> 0.33448998 | E14: =IF(D14="","",IF(D14>=3,$A$47,$A$48)) -> ไม่ได้ตามเป้าหมาย | F14: =SUMIFS(มูลค่าซื้อ!$D$15:$D$1012,มูลค่าซื้อ!$C$15:$C$1012,'สรุป-รายเดือน'!$A14,มูลค่าซื้อ!$B$15:$B$1012,'สรุป-รายเดือน'!$M$1) -> 0 | G14: =SUMIFS(Data!$L$3:$L$9021,Data!$B$3:$B$9021,'สรุป-รายเดือน'!$A14,Data!$A$3:$A$9021,'สรุป-รายเดือน'!$M$1) -> 0 | H14: =F14*0.03 -> 0 | I14: =(G14/F14)*100 -> #DIV/0! | J14: =IF(I14="","",IF(I14>=3,$A$47,$A$48)) -> #DIV/0! | L14: =G14-H14 -> 0 | M14: =L14/H14 -> #DIV/0!
A15: รวม | B15: =SUM(B3:B14) -> 7.0379458e+08 | C15: =SUM(C3:C14) -> 9594568.7 | D15: =IF(B15="","",(C15/B15)*100) -> 1.3632626 | E15: =IF(D15="","",IF(D15>=3,$A$47,$A$48)) -> ไม่ได้ตามเป้าหมาย | F15: =SUM(F3:F14) -> 6.4520953e+08 | G15: =SUM(G3:G14) -> 25785570 | H15: =SUM(H3:H14) -> 19356286 | I15: =IF(F15="","",(G15/F15)*100) -> 3.9964645 | J15: =IF(I15="","",IF(I15>=3,$A$47,$A$48)) -> ได้ตามเป้าหมาย
A36: รับทราบผลการดำเนินการงาน | G36: คุณปวิณา ใจดี
G37: คุณธนิดา ธรรมสุนทร
G38: คุณยุวนิต โนจันทร์
A47: ได้ตามเป้าหมาย
A48: ไม่ได้ตามเป้าหมาย

Sheet Sheet2
A2: MONTHLY PERFORMANCE
A4: Month | B4: Purchase Value (MB) | C4: Cost Reduction (MB) | D4: % Saving | E4: Status
A5: JAN | B5: 121.5 | C5: 8.06 | D5: 0.0663
A6: FEB | B6: 69.4 | C6: 1.78 | D6: 0.0257
A7: MAR | B7: 126.8 | C7: 3.86 | D7: 0.0304
A8: APR | B8: 57.8 | C8: 0.74 | D8: 0.0128
A9: MAY | B9: 66.1 | C9: 1.64 | D9: 0.0248
A10: JUN | B10: 92.2 | C10: 6.01 | D10: 0.0652
A11: JUL | B11: 111.3 | C11: 4.13 | D11: 0.0371
A12: AUG
A13: SEP
A14: OCT
A15: NOV
A16: Total | B16: =SUM(B5:B15) -> 645.1 | C16: =SUM(C5:C15) -> 26.22 | D16: =C16/B16 -> 0.040644861

Sheet สรุป-รายปี
B2: Year | C2: Purchase Value | D2: Actual Cost saving | E2: % Cost Saving
B3: 2023 | C3: =SUMIF(มูลค่าซื้อ!$B$15:$B$29,'สรุป-รายปี'!$B3,มูลค่าซื้อ!$D$15:$D$1012) -> 0 | D3: =SUMIF(Data!$A$3:$A$9021,'สรุป-รายปี'!$B3,Data!$L$3:$L$9021) -> 12809342 | E3: =D3/C3 -> #DIV/0!
B4: 2024 | C4: =SUMIF(มูลค่าซื้อ!$B$15:$B$29,'สรุป-รายปี'!$B4,มูลค่าซื้อ!$D$15:$D$1012) -> 1.9384578e+08 | D4: =SUMIF(Data!$A$3:$A$9021,'สรุป-รายปี'!$B4,Data!$L$3:$L$9021) -> 19695502 | E4: =D4/C4 -> 0.10160397
B5: 2025 | C5: =SUMIF(มูลค่าซื้อ!$B$15:$B$29,'สรุป-รายปี'!$B5,มูลค่าซื้อ!$D$15:$D$1012) -> 1.5730847e+09 | D5: =SUMIF(Data!$A$3:$A$9021,'สรุป-รายปี'!$B5,Data!$L$3:$L$9021) -> 38838937 | E5: =D5/C5 -> 0.024689667
B6: 2026 | E6: =D6/C6 -> #DIV/0!
B7: 2027 | E7: =D7/C7 -> #DIV/0!
B8: 2028 | E8: =D8/C8 -> #DIV/0!
B9: 2029 | E9: =D9/C9 -> #DIV/0!
B10: 2030 | E10: =D10/C10 -> #DIV/0!

Sheet มูลค่าซื้อ
B2: Year | C2: Month | D2: มูลค่าซื้อ
B3: 2026 | C3: JAN | D3: 1.215226e+08
B4: 2026 | C4: FEB | D4: 69378145
B5: 2026 | C5: MAR | D5: 1.2676433e+08
B6: 2026 | C6: APR | D6: 59523810
B7: 2026 | C7: MAY
B8: 2026 | C8: JUN
B9: 2026 | C9: JUL
B10: 2026 | C10: AUG
B11: 2026 | C11: SEP
B12: 2026 | C12: OCT
B13: 2026 | C13: NOV
B14: 2026 | C14: DEC
B15: 2025 | C15: JAN | D15: 66670985
B16: 2025 | C16: FEB | D16: 90191462
B17: 2025 | C17: MAR | D17: 1.797336e+08
B18: 2025 | C18: APR | D18: 90835578
B19: 2025 | C19: MAY | D19: 1.3899042e+08
B20: 2025 | C20: JUN | D20: 52302145
B21: 2025 | C21: JUL | D21: 2.2804367e+08
B22: 2025 | C22: AUG | D22: 79172245
B23: 2025 | C23: SEP | D23: 86561617
B24: 2025 | C24: OCT | D24: 75043726
B25: 2025 | C25: NOV | D25: 80914511
B26: 2025 | C26: DEC | D26: 4.0462472e+08
... B50: 2023 | C50: DEC | D50: 37586872

Sheet Improve#1
K1: =SUM(K4:K1248) -> 28850082
A3: Month | B3: PO No. | C3: Supplier Name. | D3: Description of Goods/Service | E3: Qty | F3: Unit | G3: ราคาต่ำสุดต่อหน่วย | H3: ราคารวม | I3: ราคาที่ต่อรองได้ | J3: ผลต่าง | K3: รวมที่ต่อรองได้ | L3: % discount | M3: Method for discounts | N3: Person in charge
A4: JAN | B4: PO-25000007 | C4: POSCO International (Thailand) CO., LTD. | D4: Silicon Steel Master Coil 023CLF080 | E4: 80000 | F4: kg. | G4: 75.5 | H4: =G4*E4 -> 6040000 | I4: 75 | J4: =G4-I4 -> 0.5 | K4: =J4*E4 -> 40000 | L4: =J4/G4 -> 0.0066225166 | M4: Compare + Negotiate | N4: Pawina | O4: Compare + Negotiate
A5: JAN | B5: PO-25000012 | C5: บริษัท เอ วี เอ เอ็นจิเนียริ่ง เซอร์วิส จำกัด | D5: แกนแรงสูง ขนาด 12 มม. ผลิตจากกระบวนการ Forging (รูเข้าสายขนา | E5: 500 | F5: EA | G5: 89 | H5: =G5*E5 -> 44500 | I5: 87 | J5: =G5-I5 -> 2 | K5: =J5*E5 -> 1000 | L5: =J5/G5 -> 0.02247191 | M5: Negotiate | N5: Pawina | O5: Avoidance
A6: JAN | B6: PO-25000012 | C6: บริษัท เอ วี เอ เอ็นจิเนียริ่ง เซอร์วิส จำกัด | D6: หางปลาแรงต่ำแบบบาร์ 6 รู แกน 58 มม. | E6: 40 | F6: EA | G6: 4980 | H6: =G6*E6 -> 199200 | I6: 4960 | J6: =G6-I6 -> 20 | K6: =J6*E6 -> 800 | L6: =J6/G6 -> 0.0040160643 | M6: Negotiate | N6: Pawina | O6: เพิ่มเครดิต
A7: JAN | B7: PO-25000012 | C7: บริษัท เอ วี เอ เอ็นจิเนียริ่ง เซอร์วิส จำกัด | D7: คลับทองเหลือง แกนแรงต่ำขนาด 30 มม. เบอร์ 3 (แบบต๊าปเกลียว) | E7: 4 | F7: EA | G7: 475 | H7: =G7*E7 -> 1900 | I7: 465 | J7: =G7-I7 -> 10 | K7: =J7*E7 -> 40 | L7: =J7/G7 -> 0.021052632 | M7: Negotiate | N7: Pawina | O7: Rebate
A8: JAN | B8: PO-25000012 | C8: บริษัท เอ วี เอ เอ็นจิเนียริ่ง เซอร์วิส จำกัด | D8: หางปลาแรงต่ำแบบบาร์ 5 รู แกน 58 มม. ระยะห่าง 80 มม. แถวเดี่ย | E8: 4 | F8: EA | G8: 6850 | H8: =G8*E8 -> 27400 | I8: 6680 | J8: =G8-I8 -> 170 | K8: =J8*E8 -> 680 | L8: =J8/G8 -> 0.024817518 | M8: Negotiate | N8: Pawina | O8: Negotiate
A9: JAN | B9: PO-25000016 | C9: บริษัท สหมิตรไวร์ แอนด์ เคเบิ้ล จำกัด | D9: ลวดแบนหุ้มกระดาษหนา 0.5 มม. | E9: 580 | F9: KG | G9: 378 | H9: =G9*E9 -> 219240 | I9: 348 | J9: =G9-I9 -> 30 | K9: =J9*E9 -> 17400 | L9: =J9/G9 -> 0.079365079 | M9: Compare + Negotiate | N9: Tanida
A10: JAN | B10: PO-25000006 | C10: บริษัท พี ซี อีลีแมค จำกัด | D10: Steel Enclosure ขนาด 2000 x 2600 x 2600 mm. | E10: 8 | F10: set | G10: 129000 | H10: =G10*E10 -> 1032000 | I10: 125000 | J10: =G10-I10 -> 4000 | K10: =J10*E10 -> 32000 | L10: =J10/G10 -> 0.031007752 | M10: Compare + Negotiate | N10: Pawina
A11: JAN | B11: PO-25000034 | C11: บริษัท สยาม วิน บอร์น จำกัด | D11: เหล็กแผ่น SS400 หนา 9.0 มม. กว้าง 1219 มม. ยาว 2438 มม. | E11: 20 | F11: แผ่น | G11: 3195 | H11: =G11*E11 -> 63900 | I11: 3190 | J11: =G11-I11 -> 5 | K11: =J11*E11 -> 100 | L11: =J11/G11 -> 0.0015649452 | M11: Compare + Negotiate | N11: Pawina
A12: JAN | B12: PO-25000034 | C12: บริษัท สยาม วิน บอร์น จำกัด | D12: เหล็กแผ่น SS400 หนา 6.0 มม. กว้าง 1219 มม. ยาว 2438 มม. | E12: 2 | F12: แผ่น | G12: 4730 | H12: =G12*E12 -> 9460 | I12: 4695 | J12: =G12-I12 -> 35 | K12: =J12*E12 -> 70 | L12: =J12/G12 -> 0.0073995772 | M12: Compare + Negotiate | N12: Pawina
A13: JAN | B13: PO-25000036 | C13: ห้างหุ้นส่วนจำกัด เอ็ม.เอ็น. อีเล็คทริค ซัพพลาย | D13: หางปลาต่อสายแบบกลมเปลือย ยี่ห้อ T-LUG CL50-12 | E13: 200 | F13: EA | G13: 15.5 | H13: =G13*E13 -> 3100 | I13: 14.76 | J13: =G13-I13 -> 0.74 | K13: =J13*E13 -> 148 | L13: =J13/G13 -> 0.047741935 | M13: Compare + Negotiate | N13: Tanida
A14: JAN | B14: PO-25000036 | C14: ห้างหุ้นส่วนจำกัด เอ็ม.เอ็น. อีเล็คทริค ซัพพลาย | D14: YAZAKI สายไฟ CVV 12 x1.5sq.mm. | E14: 50 | F14: Metre | G14: 155 | H14: =G14*E14 -> 7750 | I14: 152 | J14: =G14-I14 -> 3 | K14: =J14*E14 -> 150 | L14: =J14/G14 -> 0.019354839 | M14: Compare + Negotiate | N14: Tanida
A15: JAN | B15: PO-25000038 | C15: บริษัท ศูนย์บริการเหล็กสยาม จำกัด (มหาชน) | D15: Cold Rolled Steel Sheet (SPCC-SD) ขนาด 1.2*500 มม. | E15: 3000 | F15: KG | G15: 30 | H15: =G15*E15 -> 90000 | I15: 28 | J15: =G15-I15 -> 2 | K15: =J15*E15 -> 6000 | L15: =J15/G15 -> 0.066666667 | M15: Compare + Negotiate | N15: Pawina
A16: JAN | B16: PO-25000038 | C16: บริษัท ศูนย์บริการเหล็กสยาม จำกัด (มหาชน) | D16: Cold Rolled Steel Sheet (SPCC-SD) ขนาด 1.2*800 มม. | E16: 3000 | F16: KG | G16: 30 | H16: =G16*E16 -> 90000 | I16: 28 | J16: =G16-I16 -> 2 | K16: =J16*E16 -> 6000 | L16: =J16/G16 -> 0.066666667 | M16: Compare + Negotiate | N16: Pawina
A17: JAN | B17: PO-25000038 | C17: บริษัท ศูนย์บริการเหล็กสยาม จำกัด (มหาชน) | D17: Cold Rolled Steel Sheet (SPCC-SD) ขนาด 1.5*1100 มม. | E17: 3000 | F17: KG | G17: 30 | H17: =G17*E17 -> 90000 | I17: 28 | J17: =G17-I17 -> 2 | K17: =J17*E17 -> 6000 | L17: =J17/G17 -> 0.066666667 | M17: Compare + Negotiate | N17: Pawina
A18: JAN | B18: PO-25000038 | C18: บริษัท ศูนย์บริการเหล็กสยาม จำกัด (มหาชน) | D18: Cold Rolled Steel Sheet (SPCC-SD) ขนาด 1.5*1200 มม. | E18: 6000 | F18: KG | G18: 30 | H18: =G18*E18 -> 180000 | I18: 28 | J18: =G18-I18 -> 2 | K18: =J18*E18 -> 12000 | L18: =J18/G18 -> 0.066666667 | M18: Compare + Negotiate | N18: Pawina
A19: JAN | B19: PO-25000040 | C19: บริษัท ยูไนเต็ดคอปเปอร์ จำกัด | D19: ทองแดงเส้นแบน | E19: 578 | F19: KG | G19: 375 | H19: =G19*E19 -> 216750 | I19: 355 | J19: =G19-I19 -> 20 | K19: =J19*E19 -> 11560 | L19: =J19/G19 -> 0.053333333 | M19: Compare + Negotiate | N19: Tanida
A20: JAN | B20: PO-25000041 | C20: บริษัท เจริญทรัพย์ พาเลท จำกัด | D20: Wooden Crate Tr.16 MVA (Fumigation) | E20: 1 | F20: SET | G20: 7650 | H20: =G20*E20 -> 7650 | I20: 5870 | J20: =G20-I20 -> 1780 | K20: =J20*E20 -> 1780 | L20: =J20/G20 -> 0.23267974 | M20: Compare + Negotiate | N20: Tanida
... A34: JAN | B34: PO-25000140 | C34: บริษัท บางกอกแม็กเน็ตไวร์ จำกัด | D34: ลวดกลมอาบน้ำยา | E34: 17400 | F34: KG | G34: 7 | H34: =G34*E34 -> 121800 | I34: 0 | J34: =G34-I34 -> 7 | K34: =J34*E34 -> 121800 | L34: =J34/G34 -> 1 | M34: Negotiate | N34: Tanida
A35: JAN | C35: บริษัท ทีโอเอ-ชูโกกุ เพ้นท์ จำกัด | D35: Rebate ปี2567 | E35: 1 | F35: JOB | G35: 10124405 | H35: =G35*E35 -> 10124405 | I35: 9820672.8 | J35: =G35-I35 -> 303732.15 | K35: =J35*E35 -> 303732.15 | L35: =J35/G35 -> 0.03 | M35: Rebate | N35: Saniya
A36: JAN | B36: PO-25000019 | C36: บริษัท ทีโอเอ-ชูโกกุ เพ้นท์ จำกัด | D36: สีทับหน้า (PU) RAL 7032 CHUGOKU UNY MARINE 100 (DH) | E36: 200 | F36: ถัง | G36: 4700 | H36: =G36*E36 -> 940000 | I36: 4400 | J36: =G36-I36 -> 300 | K36: =J36*E36 -> 60000 | L36: =J36/G36 -> 0.063829787 | M36: Negotiate | N36: Saniya
A37: JAN | B37: PO-25000021 | C37: บริษัท ไทยสเปเชี่ยลแก๊ส จำกัด | D37: ไนโตรเจน | E37: 5 | F37: ถัง | G37: 240 | H37: =G37*E37 -> 1200 | I37: 168 | J37: =G37-I37 -> 72 | K37: =J37*E37 -> 360 | L37: =J37/G37 -> 0.3 | M37: Compare + Negotiate | N37: Saniya
A38: JAN | B38: PO-25000031 | C38: บริษัท ดีเอสไอ คอร์ปอเรชั่น จำกัด | D38: Scotch 3M Filament Tape 48 มม. x 50 มม. เทปใยแก้ว | E38: 144 | F38: Roll | G38: 405 | H38: =G38*E38 -> 58320 | I38: 385 | J38: =G38-I38 -> 20 | K38: =J38*E38 -> 2880 | L38: =J38/G38 -> 0.049382716 | M38: Avoidance | N38: Saniya
A39: JAN | B39: PO-25000051 | C39: บริษัท เอเทค ลิฟท์ติ้ง ทูลส์ จำกัด | D39: สลิงโพลีฯชนิดกลมมีห่วงหัว-ท้าย รับ นน.10T ยาว 4ม. สีส้ม | E39: 1 | F39: EA | G39: 4230 | H39: =G39*E39 -> 4230 | I39: 2800 | J39: =G39-I39 -> 1430 | K39: =J39*E39 -> 1430 | L39: =J39/G39 -> 0.33806147 | M39: Compare + Negotiate | N39: Saniya
A40: JAN | B40: PO-25000061 | C40: บริษัท ไทยพัฒนสิน (จิ้นเส็ง 2000) จำกัด | D40: POLO ดอกเจาะเหล็กคัตเตอร์คาร์ไบด์ Dia.16x35มม. | E40: 5 | F40: EA | G40: 780 | H40: =G40*E40 -> 3900 | I40: 720 | J40: =G40-I40 -> 60 | K40: =J40*E40 -> 300 | L40: =J40/G40 -> 0.076923077 | M40: Compare + Negotiate | N40: Saniya
A41: JAN | B41: PO-25000061 | C41: บริษัท ไทยพัฒนสิน (จิ้นเส็ง 2000) จำกัด | D41: POLO ดอกเจาะเหล็กคัตเตอร์คาร์ไบด์ Dia.18x35มม. | E41: 4 | F41: EA | G41: 780 | H41: =G41*E41 -> 3120 | I41: 720 | J41: =G41-I41 -> 60 | K41: =J41*E41 -> 240 | L41: =J41/G41 -> 0.076923077 | M41: Compare + Negotiate | N41: Saniya
A42: JAN | B42: PO-25000061 | C42: บริษัท ไทยพัฒนสิน (จิ้นเส็ง 2000) จำกัด | D42: POLO ดอกเจาะเหล็กคัตเตอร์คาร์ไบด์ Dia.22x35มม. | E42: 8 | F42: EA | G42: 780 | H42: =G42*E42 -> 6240 | I42: 720 | J42: =G42-I42 -> 60 | K42: =J42*E42 -> 480 | L42: =J42/G42 -> 0.076923077 | M42: Compare + Negotiate | N42: Saniya
A43: JAN | B43: PO-25000061 | C43: บริษัท ไทยพัฒนสิน (จิ้นเส็ง 2000) จำกัด | D43: POLO ดอกเจาะเหล็กคัตเตอร์คาร์ไบด์ Dia.25x35มม. | E43: 3 | F43: EA | G43: 780 | H43: =G43*E43 -> 2340 | I43: 720 | J43: =G43-I43 -> 60 | K43: =J43*E43 -> 180 | L43: =J43/G43 -> 0.076923077 | M43: Compare + Negotiate | N43: Saniya
A44: JAN | B44: PO-25000061 | C44: บริษัท ไทยพัฒนสิน (จิ้นเส็ง 2000) จำกัด | D44: POLO ดอกเจาะเหล็กคัตเตอร์คาร์ไบด์ Dia.28x35มม. | E44: 3 | F44: EA | G44: 882 | H44: =G44*E44 -> 2646 | I44: 820 | J44: =G44-I44 -> 62 | K44: =J44*E44 -> 186 | L44: =J44/G44 -> 0.070294785 | M44: Compare + Negotiate | N44: Saniya
A45: JAN | B45: PO-25000061 | C45: บริษัท ไทยพัฒนสิน (จิ้นเส็ง 2000) จำกัด | D45: POLO ดอกเจาะเหล็กคัตเตอร์คาร์ไบด์ Dia.30x35มม. | E45: 3 | F45: EA | G45: 882 | H45: =G45*E45 -> 2646 | I45: 820 | J45: =G45-I45 -> 62 | K45: =J45*E45 -> 186 | L45: =J45/G45 -> 0.070294785 | M45: Compare + Negotiate | N45: Saniya
A46: JAN | B46: PO-25000070 | C46: บริษัท เอทีซี อินดัสตรี (ประเทศไทย)จำกัด | D46: สีรองพื้น TOA Red Oxide primer G1024D Size 18.925ลิตร/ถัง | E46: 20 | F46: ถัง | G46: 2150 | H46: =G46*E46 -> 43000 | I46: 2135 | J46: =G46-I46 -> 15 | K46: =J46*E46 -> 300 | L46: =J46/G46 -> 0.0069767442 | M46: Compare + Negotiate | N46: Saniya
A47: JAN | B47: PO-25000070 | C47: บริษัท เอทีซี อินดัสตรี (ประเทศไทย)จำกัด | D47: สก๊อตเทปใส Unitape size 1/2" IN x 72 YDS | E47: 576 | F47: Roll | G47: 32 | H47: =G47*E47 -> 18432 | I47: 25 | J47: =G47-I47 -> 7 | K47: =J47*E47 -> 4032 | L47: =J47/G47 -> 0.21875 | M47: Compare + Negotiate | N47: Saniya
... A85: JAN | B85: PO-25000133 | C85: บริษัท เอเบิล ซัคเซส จำกัด | D85: ZWCAD Standard 2025 Standalone License (CAD 2D) Training ( 5 | E85: 5 | F85: EA | G85: 32900 | H85: =G85*E85 -> 164500 | I85: 30000 | J85: =G85-I85 -> 2900 | K85: =J85*E85 -> 14500 | L85: =J85/G85 -> 0.088145897 | M85: Negotiate | N85: Saniya
A86: JAN | B86: PO-25000134 | C86: บริษัท พี เอ็น เทค จำกัด | D86: EQUIPMENT PRODUCT - MANUAL PUSH STATION (FMM) | E86: 1 | F86: JOB | G86: 343500 | H86: =G86*E86 -> 343500 | J86: =G86-I86 -> 343500 | K86: =J86*E86 -> 343500 | L86: =J86/G86 -> 1 | M86: Negotiate | N86: Saniya
A87: JAN | B87: PO-25000165 | C87: บริษัท เอ วี เอ เอ็นจิเนียริ่ง เซอร์วิส จำกัด | D87: แกนทองแดง 12 มม. เบอร์ 1 | E87: 501 | F87: EA | G87: 147 | H87: =G87*E87 -> 73647 | I87: 136 | J87: =G87-I87 -> 11 | K87: =J87*E87 -> 5511 | L87: =J87/G87 -> 0.074829932 | M87: Negotiate | N87: Pawina
A88: JAN | B88: PO-25000165 | C88: บริษัท เอ วี เอ เอ็นจิเนียริ่ง เซอร์วิส จำกัด | D88: แกนทองแดง 30 มม. เบอร์ 3 | E88: 493 | F88: EA | G88: 1100 | H88: =G88*E88 -> 542300 | I88: 1070 | J88: =G88-I88 -> 30 | K88: =J88*E88 -> 14790 | L88: =J88/G88 -> 0.027272727 | M88: Negotiate | N88: Pawina
A89: JAN | B89: PO-25000165 | C89: บริษัท เอ วี เอ เอ็นจิเนียริ่ง เซอร์วิส จำกัด | D89: แหวนหนา แกน 30 มม. | E89: 473 | F89: EA | G89: 185 | H89: =G89*E89 -> 87505 | I89: 180 | J89: =G89-I89 -> 5 | K89: =J89*E89 -> 2365 | L89: =J89/G89 -> 0.027027027 | M89: Negotiate | N89: Pawina
A90: JAN | B90: PO-25000165 | C90: บริษัท เอ วี เอ เอ็นจิเนียริ่ง เซอร์วิส จำกัด | D90: หางปลาแรงต่ำแบบบาร์ 4 รู แกน 30 มม. (PEA) | E90: 300 | F90: EA | G90: 885 | H90: =G90*E90 -> 265500 | I90: 865 | J90: =G90-I90 -> 20 | K90: =J90*E90 -> 6000 | L90: =J90/G90 -> 0.02259887 | M90: Negotiate | N90: Pawina
A91: JAN | B91: PO-25000170 | C91: บริษัท เอ็น.เอช.เค.สตีล จำกัด | D91: Cold Rolled Steel Sheet (SPCC-SD) | E91: 12000 | F91: KG | G91: 29.8 | H91: =G91*E91 -> 357600 | I91: 28 | J91: =G91-I91 -> 1.8 | K91: =J91*E91 -> 21600 | L91: =J91/G91 -> 0.060402685 | M91: Compare + Negotiate | N91: Pawina
...

Sheet Sheet4
A3: Sum of รวมที่ต่อรองได้ | B3: Column Labels
A4: Row Labels | B4: Dusit | C4: Pawina | D4: Saniya | E4: Tanida | F4: Yuwanit | G4: Grand Total
A5: Avoidance | C5: 242550 | D5: 6960 | E5: 735860 | G5: 985370
A6: Compare + Negotiate | C6: 8720352.6 | D6: 329680.5 | E6: 6428412.4 | F6: 71303.3 | G6: 15549749
A7: Negotiate | B7: 143426.59 | C7: 2917633.7 | D7: 553322 | E7: 2851246.4 | F7: 293198.51 | G7: 6758827.2
A8: Rebate | D8: 303732.15 | G8: 303732.15
A9: เพิ่มเครดิต | B9: 82234.93 | C9: 70.13 | F9: 3364.58 | G9: 85669.64
A10: Grand Total | B10: 225661.52 | C10: 11880606 | D10: 1193694.7 | E10: 10015519 | F10: 367866.39 | G10: 23683348
A13: กลยุทธ์ด้านจัดซื้อ | B13: รวมมูลค่าที่ต่อรองได้ ปี 2568 (บาท) | H13: สัดส่วน
B14: Dusit | C14: Pawina | D14: Saniya | E14: Tanida | F14: Yuwanit | G14: Grand Total
A15: Avoidance | C15: 242550 | D15: 6960 | E15: 735860 | G15: 985370 | H15: =G15/G$20 -> 0.041606027
A16: Compare + Negotiate | C16: 8720352.6 | D16: 329680.5 | E16: 6428412.4 | F16: 71303.3 | G16: 15549749 | H16: =G16/G$20 -> 0.65656886
A17: Negotiate | B17: 143426.59 | C17: 2917633.7 | D17: 553322 | E17: 2851246.4 | F17: 293198.51 | G17: 6758827.2 | H17: =G17/G$20 -> 0.2853831
A18: Rebate | D18: 303732.15 | G18: 303732.15 | H18: =G18/G$20 -> 0.012824713
A19: เพิ่มเครดิต Extend Credit terms | B19: 82234.93 | C19: 70.13 | F19: 3364.58 | G19: 85669.64 | H19: =G19/G$20 -> 0.0036172943
A20: Grand Total (บาท) | B20: 225661.52 | C20: 11880606 | D20: 1193694.7 | E20: 10015519 | F20: 367866.39 | G20: 23683348 | H20: =SUM(H15:H19) -> 1

Sheet Kaizen Cost saving 
C2: ประหยัดเวลาได้ | D2: 10 | F2: นาที/งาน
C3: จำนวนงาน | D3: 16 | F3: =IF(H3=TRUE,"งาน/วัน","งาน/เดือน") -> งาน/เดือน | H3: FALSE
C5: ค่าแรง | D5: =(19625/21)/8 -> 116.81548 | F5: บาท/ชั่วโมง
C6: ทำงาน | D6: 20 | F6: วัน/เดือน
C7: จำนวน | D7: 1 | F7: เดือน/ปี
C10: คิดเป็นผลประหยัด | D10: =IF(H3=TRUE,"("&D2&"/60) x "&D3&" x "&117&" x "&D6&" x "&D7,"("&D2&"/60) x "&D3&" x "&117&" x "&D7) -> (10/60) x 16 x 117 x 1 | H10: บาท/ปี
D12: =IF(H3=TRUE,(D2/60)*D5*D3*D6*D7,(D2/60)*D5*D3*D7) -> 311.50794 | H12: บาท/ปี
C14: Update ค่าแรงต่อชั่วโมง จาก 98.5 บาท/ชม.เป็น 117 บาท/ชม. เมื่อวันที่ 25/02/65
C15: หมายเหตุ
C16: ราคากระดาษแผ่นละ 0.15 บาท
C17: ค่าแรงพนักงานเฉลี่ยทั้งบริษัทเป็น 117 บาท/ชั่วโมง
C18: วิธีการคิดลดการใช้พลังงานเป็นจำนวนเงิน
C19: กิโลวัตต์-ชั่วโมงต่อปี û หน่วยค่าไฟฟ้า (หน่วยละ 4 บาท) เช่น 173*4=692 บาท
C20: ค่าปริ้นท์สี | D20: 3 | E20: บาทต่อแผ่น
C21: ค่าปริ้นท์ขาวดำ | D21: 0.3 | E21: บาทต่อแผ่น

Sheet Set
B1: Month
B2: JAN | C2: 1
B3: FEB | C3: 2
B4: MAR | C4: 3
B5: APR | C5: 4
B6: MAY | C6: 5
B7: JUN | C7: 6
B8: JUL | C8: 7
B9: AUG | C9: 8
B10: SEP | C10: 9
B11: OCT | C11: 10
B12: NOV | C12: 11
B13: DEC | C13: 12
